Workbook

Sheet 10
A7: DAFTAR MURID TAHUN AJARAN 2026/2027
A8: Kelas : X-A
A9: No | D9: Nama | E9: L/P | F9: Agm | G9: Mapel Seni
A10: Urt | B10: Induk | C10: NISN
A11: 1 | B11: 10273 | C11: 0109933591 | D11: ADELLIA DINNANTY SAPNA | E11: P | F11: Isl | G11: Rupa
A12: 2 | B12: 10295 | C12: 0116305799 | D12: ALVITA OLA RALITA | E12: P | F12: Kri | G12: Musik
A13: 3 | B13: 10296 | C13: 0107369712 | D13: AMELIA ANGGRAINI | E13: P | F13: Isl | G13: Musik
A14: 4 | B14: 10304 | C14: 0104956415 | D14: ANOM PUTRA WIBOWO | E14: L | F14: Isl | G14: Rupa
A15: 5 | B15: 10310 | C15: 0117051459 | D15: ATHANIA IKA NURLIA | E15: P | F15: Isl | G15: Musik
A16: 6 | B16: 10317 | C16: 0108846722 | D16: AYANA NUR AFINA | E16: P | F16: Isl | G16: Rupa
A17: 7 | B17: 10321 | C17: 0112711157 | D17: BAIQ KANIA KHAIRUNNISA | E17: P | F17: Isl | G17: Rupa
A18: 8 | B18: 10328 | C18: 0102800161 | D18: CAETRINE NIAMI | E18: P | F18: Kri | G18: Musik
A19: 9 | B19: 10329 | C19: 0102467225 | D19: CALLISTA QAULA PRAJA | E19: P | F19: Isl | G19: Rupa
A20: 10 | B20: 10332 | C20: 0117157210 | D20: CHRISNA WIRA DILAGA | E20: L | F20: Kri | G20: Musik
A21: 11 | B21: 10342 | C21: 0114184267 | D21: DIONISIUS ANUGERAH | E21: L | F21: Kri | G21: Musik
A22: 12 | B22: 10344 | C22: 0113709169 | D22: DORMA CITRA SAHRATULANI NAINGGOLAN | E22: P | F22: Kri | G22: Musik
... A46: 36 | B46: 10510 | C46: 0105159965 | D46: WARIH RACHMAN HAKIM | E46: L | F46: Isl | G46: Musik
A47: L | B47: =COUNTIF(E11:E46,A47) -> 10 | C47: Siswa | D47: Isl | E47: =COUNTIF(F11:F46,D47) -> 23
A48: P | B48: =COUNTIF(E11:E46,A48) -> 26 | C48: Siswa | D48: Kri | E48: =COUNTIF(F11:F46,D48) -> 13
A49: Jm | B49: =B47+B48 -> 36 | C49: Siswa | D49: Kat | E49: =COUNTIF(F11:F46,D49) -> 0
D50: Musik | E50: =COUNTIF(G11:G46,D50) -> 19
D51: Rupa | E51: =COUNTIF(G11:G46,D51) -> 17
A52: Kelas : X-B
A53: No | D53: Nama | E53: L/P | F53: Agm | G53: Mapel Seni
A54: Urt | B54: Induk | C54: NISN
A55: 1 | B55: 10276 | C55: 0121241305 | D55: AGATHA OLIVIA PUTRI | E55: P | F55: Kat | G55: Musik
A56: 2 | B56: 10278 | C56: 0105799113 | D56: AGUSTINUS VERGINANDO KENZI PRATAMA | E56: L | F56: Kat | G56: Musik
A57: 3 | B57: 10282 | C57: 0101599274 | D57: AIS ALKORI | E57: P | F57: Isl | G57: Rupa
A58: 4 | B58: 10298 | C58: 0119446611 | D58: ANASTASYA GALUH ANINDITA | E58: P | F58: Kat | G58: Rupa
A59: 5 | B59: 10303 | C59: 0107520799 | D59: ANNISA DWI FITRIANI | E59: P | F59: Isl | G59: Rupa
A60: 6 | B60: 10313 | C60: 0108815140 | D60: AULIA LAYLA ABDILLAH | E60: P | F60: Isl | G60: Rupa
A61: 7 | B61: 10330 | C61: 0109959911 | D61: CARISSA RISTINIA AUDREY | E61: P | F61: Isl | G61: Rupa
A62: 8 | B62: 10331 | C62: 0117229998 | D62: CHASNA' ANEEQA NUR'AINI | E62: P | F62: Isl | G62: Rupa
A63: 9 | B63: 10336 | C63: 0112253770 | D63: CYRILLA SVITZVALENZA DIOVANKA ASMARA | E63: P | F63: Kat | G63: Musik
A64: 10 | B64: 10340 | C64: 0102494081 | D64: DEA GYSCA RAFANI PUTRI | E64: P | F64: Isl | G64: Musik
A65: 11 | B65: 10366 | C65: 0112465743 | D65: GERARDUS PRADANA WIBISONO SANTOSA | E65: L | F65: Kat | G65: Musik
A66: 12 | B66: 10369 | C66: 0101233309 | D66: GRACIA BETREACE QUENNEL VALENTINE WANDAPUTRI | E66: P | F66: Kat | G66: Musik
... A90: 36 | B90: 10517 | C90: 0108447472 | D90: ZAHRA ADZKIA MUTHMAINAH | E90: P | F90: Isl | G90: Musik
A91: L | B91: =COUNTIF(E55:E90,A91) -> 10 | C91: Siswa | D91: Isl | E91: =COUNTIF(F55:F90,D91) -> 21
A92: P | B92: =COUNTIF(E55:E90,A92) -> 26 | C92: Siswa | D92: Kri | E92: =COUNTIF(F55:F90,D92) -> 0
...

Sheet 11
A7: DAFTAR MURID TAHUN AJARAN 2026/2027
A8: Kelas : XI-A, Mapel pilihan : Bio, Kim, Antro, Sos
A9: No | D9: Nama | E9: L/P | F9: Agm | G9: Mapel Seni
A10: Urt | B10: Induk | C10: NISN
A11: 1 | B11: 10020 | C11: 0093164669 | D11: AFALA KARLA MAJID | E11: P | F11: Isl | G11: Musik
A12: 2 | B12: 10027 | C12: 0099659265 | D12: AISA IFFATUSSOLIHA | E12: P | F12: Isl | G12: Musik
A13: 3 | B13: 10036 | C13: 0097927590 | D13: ALMIRA RAMADHINTA | E13: P | F13: Isl | G13: Rupa
A14: 4 | B14: 10041 | C14: 0093093783 | D14: ANDINA WULAN RAHMADANI | E14: P | F14: Isl | G14: Musik
A15: 5 | B15: 10042 | C15: 0107309612 | D15: ANDIRATU LIEBISYA | E15: P | F15: Isl | G15: Rupa
A16: 6 | B16: 10046 | C16: 0104863682 | D16: ANIES PRAMUDYA YUNISSA | E16: P | F16: Isl | G16: Musik
A17: 7 | B17: 10047 | C17: 0092061539 | D17: ANINDYA ANITA WIDYANTARI | E17: P | F17: Isl | G17: Musik
A18: 8 | B18: 10049 | C18: 3094841739 | D18: ANNISA NUR RAHMADANI | E18: P | F18: Isl | G18: Musik
A19: 9 | B19: 10059 | C19: 0098047853 | D19: AULIA RAMADHANI | E19: P | F19: Isl | G19: Musik
A20: 10 | B20: 10079 | C20: 0103784466 | D20: DAYYAN RAFIF ARKANANTA | E20: L | F20: Isl | G20: Musik
A21: 11 | B21: 10089 | C21: 0096074416 | D21: DZAKI LUKMANA | E21: L | F21: Isl | G21: Musik
A22: 12 | B22: 10093 | C22: 0096323158 | D22: ELVINOLA NERRA MAHESWARI | E22: P | F22: Isl | G22: Musik
... A46: 36 | B46: 10263 | C46: 0105261584 | D46: ZARIFAH HANIF LATIFAH | E46: P | F46: Isl | G46: Rupa
A47: L | B47: =COUNTIF(E11:E46,A47) -> 8 | C47: Siswa | D47: Isl | E47: =COUNTIF(F11:F46,D47) -> 34
A48: P | B48: =COUNTIF(E11:E46,A48) -> 28 | C48: Siswa | D48: Kri | E48: =COUNTIF(F11:F46,D48) -> 1
A49: Jm | B49: =B47+B48 -> 36 | C49: Siswa | D49: Kat | E49: =COUNTIF(F11:F46,D49) -> 1
D50: Musik | E50: =COUNTIF(G11:G46,D50) -> 25
D51: Rupa | E51: =COUNTIF(G11:G46,D51) -> 11
A52: Kelas : XI-B, Mapel pilihan : Mat-L, Fis, Kim, Bio
A53: No | D53: Nama | E53: L/P | F53: Agm | G53: Mapel Seni
A54: Urt | B54: Induk | C54: NISN
A55: 1 | B55: 10028 | C55: 0119538891 | D55: AISYAH LADITA PUTRI HANDAYANI | E55: P | F55: Isl | G55: Musik
A56: 2 | B56: 10033 | C56: 0101954540 | D56: ALIFA SIWI NURIYATUN | E56: P | F56: Isl | G56: Musik
A57: 3 | B57: 10043 | C57: 0103601998 | D57: ANGGI YULIA PRATIWI | E57: P | F57: Isl | G57: Musik
A58: 4 | B58: 10044 | C58: 0096274191 | D58: ANGGITA FITRI CAHYA RAHMADANI | E58: P | F58: Isl | G58: Musik
A59: 5 | B59: 10052 | C59: 0097709136 | D59: ARSYA RHANA ARVIANDA | E59: P | F59: Isl | G59: Musik
A60: 6 | B60: 10057 | C60: 0092968728 | D60: ATIKA RIA ISTIQOMAH | E60: P | F60: Isl | G60: Rupa
A61: 7 | B61: 10069 | C61: 0105723794 | D61: CAHYA RESTU PERMADI | E61: L | F61: Isl | G61: Rupa
A62: 8 | B62: 10076 | C62: 0098446995 | D62: CYNTHIA RAHMAWATI | E62: P | F62: Isl | G62: Musik
A63: 9 | B63: 10078 | C63: 0093365514 | D63: DARIEL ANGGA FADRIANZA | E63: L | F63: Isl | G63: Musik
A64: 10 | B64: 10097 | C64: 0098452220 | D64: FAIZA DAFFA MAHARDIKA | E64: L | F64: Isl | G64: Musik
A65: 11 | B65: 10102 | C65: 0093250361 | D65: FIKA MARLIDA | E65: P | F65: Isl | G65: Musik
A66: 12 | B66: 10128 | C66: 0096456361 | D66: IRSYAD CHABIBUROCHMAN HIDAYAT | E66: L | F66: Isl | G66: Rupa
... A90: 36 | B90: 10259 | C90: 0094943882 | D90: ZAHRA EARLY NASHIFA | E90: P | F90: Isl | G90: Rupa
A91: L | B91: =COUNTIF(E55:E90,A91) -> 10 | C91: Siswa | D91: Isl | E91: =COUNTIF(F55:F90,D91) -> 34
A92: P | B92: =COUNTIF(E55:E90,A92) -> 26 | C92: Siswa | D92: Kri | E92: =COUNTIF(F55:F90,D92) -> 2
...

Sheet 12
A7: DAFTAR MURID TAHUN AJARAN 2026/2027
A8: Kelas : XII-A, Mapel pilihan : Bio, Fis, Kim, Mat-L
A9: No | D9: Nama | E9: L/P | F9: Agm | G9: Mapel Seni
A10: Urt | B10: Induk | C10: NISN
A11: 1 | B11: 9764 | C11: 0098722268 | D11: ABIGAIL JASMINE ALYA DEWANTI | E11: P | F11: Isl | G11: Musik
A12: 2 | B12: 9772 | C12: 0097300072 | D12: AFIFAH MAQFIROH | E12: P | F12: Isl | G12: Musik
A13: 3 | B13: 9778 | C13: 0081757509 | D13: AHMAD KHOIRUL HUDA ROSYADAN | E13: L | F13: Isl | G13: Musik
A14: 4 | B14: 9786 | C14: 0089293035 | D14: ALBERTUS DAVIN PRATAMA | E14: L | F14: Kat | G14: Rupa
A15: 5 | B15: 9789 | C15: 0095280585 | D15: ALFIYYAH NUR FAUZIA | E15: P | F15: Isl | G15: Rupa
A16: 6 | B16: 9800 | C16: 0086307949 | D16: ANGGUN KARUNIASARI | E16: P | F16: Isl | G16: Musik
A17: 7 | B17: 9815 | C17: 0085671014 | D17: AVRELYA HANIF ANJANI | E17: P | F17: Isl | G17: Musik
A18: 8 | B18: 9819 | C18: 0083020646 | D18: BELVA PUTRI ALEXA | E18: P | F18: Isl | G18: Musik
A19: 9 | B19: 9827 | C19: 0077897295 | D19: CHELCEA OCTAVIA | E19: P | F19: Isl | G19: Rupa
A20: 10 | B20: 9834 | C20: 0083329841 | D20: DAFFA AFNAN FEYZA | E20: L | F20: Isl | G20: Musik
A21: 11 | B21: 9843 | C21: 0091673944 | D21: DIAS ANGGER WICAKSONO | E21: L | F21: Isl | G21: Musik
A22: 12 | B22: 9850 | C22: 0082700913 | D22: EKA SURYANI RAHAYU | E22: P | F22: Kat | G22: Musik
... A46: 36 | B46: 10011 | C46: 0099531940 | D46: ZAHRA ARINDANI SETYANINGRUM | E46: P | F46: Isl | G46: Musik
A47: L | B47: =COUNTIF(E11:E46,A47) -> 11 | C47: Siswa | D47: Isl | E47: =COUNTIF(F11:F46,D47) -> 33
A48: P | B48: =COUNTIF(E11:E46,A48) -> 25 | C48: Siswa | D48: Kri | E48: =COUNTIF(F11:F46,D48) -> 0
A49: Jm | B49: =B47+B48 -> 36 | C49: Siswa | D49: Kat | E49: =COUNTIF(F11:F46,D49) -> 3
D50: Musik | E50: =COUNTIF(G11:G46,D50) -> 27
D51: Rupa | E51: =COUNTIF(G11:G46,D51) -> 9
A52: Kelas : XII-B, Mapel pilihan : Bio, Fis, Kim, B. Jerm
A53: No | D53: Nama | E53: L/P | F53: Agm | G53: Mapel Seni
A54: Urt | B54: Induk | C54: NISN
A55: 1 | B55: 9799 | C55: 0082381605 | D55: ANGGITA PRIHATINA | E55: P | F55: Isl | G55: Musik
A56: 2 | B56: 9807 | C56: 0098153949 | D56: ARDINA SYAFA PRAMESTI | E56: P | F56: Isl | G56: Musik
A57: 3 | B57: 9808 | C57: 0097377350 | D57: ARSHINTA RAYYA PUTRI PURBANTORO | E57: P | F57: Isl | G57: Rupa
A58: 4 | B58: 9810 | C58: 0097712081 | D58: AULIA ARTIKA SARI | E58: P | F58: Isl | G58: Musik
A59: 5 | B59: 9813 | C59: 0093352620 | D59: AURELLIA KRISTIANTI | E59: P | F59: Isl | G59: Musik
A60: 6 | B60: 9816 | C60: 0095807578 | D60: AYRA MALIKA | E60: P | F60: Isl | G60: Rupa
A61: 7 | B61: 9830 | C61: 0092464693 | D61: CHUSNIA PUTRI NURUL A'LAA | E61: P | F61: Isl | G61: Musik
A62: 8 | B62: 9835 | C62: 0085207000 | D62: DARIN KHUSNUL MAHFUDHAH | E62: P | F62: Isl | G62: Rupa
A63: 9 | B63: 9851 | C63: 0098569842 | D63: ELISABETH CINTA CLARA PUSPITASARI | E63: P | F63: Kri | G63: Musik
A64: 10 | B64: 9854 | C64: 0096942071 | D64: ERLINDA AURA ATHALIA | E64: P | F64: Kat | G64: Musik
A65: 11 | B65: 9856 | C65: 0092508012 | D65: EURICA VALIYAN | E65: P | F65: Isl | G65: Musik
A66: 12 | B66: 9859 | C66: 0098077127 | D66: FAHRI ALI KHADAFI | E66: L | F66: Isl | G66: Musik
... A90: 36 | B90: 10012 | C90: 0091457379 | D90: ZHAFIRA ILYAKHALILA FATIHANNAFI | E90: P | F90: Isl | G90: Musik
A91: L | B91: =COUNTIF(E55:E90,A91) -> 10 | C91: Siswa | D91: Isl | E91: =COUNTIF(F55:F90,D91) -> 34
A92: P | B92: =COUNTIF(E55:E90,A92) -> 26 | C92: Siswa | D92: Kri | E92: =COUNTIF(F55:F90,D92) -> 1
...

Sheet rekap
B2: (Sementara) Formasi Kelas TA 2026/2027 | Y2: SMAN 2 Wonosari
Y3: Mapel Pilihan Kelas XI+XII TA 2026/2027
C4: X-A | D4: X-B | E4: X-C | F4: X-D | G4: X-E | H4: X-F | I4: X-G | J4: XI-A | K4: XI-B | L4: XI-C | M4: XI-D | N4: XI-E | O4: XI-F | P4: XI-G | Q4: XII-A | R4: XII-B | S4: XII-C | T4: XII-D | U4: XII-E | V4: XII-F | W4: XII-G | Y4: No | Z4: XI-A | AA4: XI-B | AB4: XI-C | AC4: XI-D | AD4: XI-E | AE4: XI-F | AF4: XI-G | AG4: XII-A | AH4: XII-B | AI4: XII-C | AJ4: XII-D | AK4: XII-E | AL4: XII-F | AM4: XII-G
B5: L | C5: ='10'!B47 -> 10 | D5: ='10'!B91 -> 10 | E5: ='10'!B135 -> 12 | F5: ='10'!B179 -> 12 | G5: ='10'!B223 -> 12 | H5: ='10'!B267 -> 12 | I5: ='10'!B311 -> 12 | J5: ='11'!B47 -> 8 | K5: ='11'!B91 -> 10 | L5: ='11'!B135 -> 20 | M5: ='11'!B179 -> 6 | N5: ='11'!B223 -> 5 | O5: ='11'!B267 -> 18 | P5: ='11'!B311 -> 18 | Q5: ='12'!B47 -> 11 | R5: ='12'!B91 -> 10 | S5: ='12'!B135 -> 4 | T5: ='12'!B179 -> 8 | U5: ='12'!B223 -> 10 | V5: ='12'!B267 -> 17 | W5: ='12'!B311 -> 19 | Y5: 1 | Z5: Bio | AA5: Mat-L | AB5: Mat-L | AC5: Fis | AD5: Geo | AE5: Geo | AF5: Geo | AG5: Bio | AH5: Bio | AI5: Bio | AJ5: Geo | AK5: Geo | AL5: Geo | AM5: Eko
B6: P | C6: ='10'!B48 -> 26 | D6: ='10'!B92 -> 26 | E6: ='10'!B136 -> 24 | F6: ='10'!B180 -> 23 | G6: ='10'!B224 -> 24 | H6: ='10'!B268 -> 24 | I6: ='10'!B312 -> 24 | J6: ='11'!B48 -> 28 | K6: ='11'!B92 -> 26 | L6: ='11'!B136 -> 16 | M6: ='11'!B180 -> 30 | N6: ='11'!B224 -> 31 | O6: ='11'!B268 -> 17 | P6: ='11'!B312 -> 18 | Q6: ='12'!B48 -> 25 | R6: ='12'!B92 -> 26 | S6: ='12'!B136 -> 32 | T6: ='12'!B180 -> 28 | U6: ='12'!B224 -> 26 | V6: ='12'!B268 -> 19 | W6: ='12'!B312 -> 13 | Y6: 2 | Z6: Kim | AA6: Fis | AB6: Fis | AC6: Kim | AD6: Eko | AE6: Eko | AF6: Sos | AG6: Fis | AH6: Fis | AI6: Fis | AJ6: Sos | AK6: Sos | AL6: Sos | AM6: B. Ing-L
B7: Isl | C7: ='10'!E47 -> 23 | D7: ='10'!E91 -> 21 | E7: ='10'!E135 -> 36 | F7: ='10'!E179 -> 35 | G7: ='10'!E223 -> 36 | H7: ='10'!E267 -> 36 | I7: ='10'!E311 -> 36 | J7: ='11'!E47 -> 34 | K7: ='11'!E91 -> 34 | L7: ='11'!E135 -> 30 | M7: ='11'!E179 -> 32 | N7: ='11'!E223 -> 29 | O7: ='11'!E267 -> 32 | P7: ='11'!E311 -> 34 | Q7: ='12'!E47 -> 33 | R7: ='12'!E91 -> 34 | S7: ='12'!E135 -> 36 | T7: ='12'!E179 -> 23 | U7: ='12'!E223 -> 33 | V7: ='12'!E267 -> 35 | W7: ='12'!E311 -> 27 | Y7: 3 | Z7: Antro | AA7: Kim | AB7: Inf | AC7: Bio | AD7: Sos | AE7: Antro | AF7: Bio | AG7: Kim | AH7: Kim | AI7: Kim | AJ7: Eko | AK7: Eko | AL7: Eko | AM7: B. Jpn
B8: Kri | C8: ='10'!E48 -> 13 | D8: ='10'!E92 -> 0 | E8: ='10'!E136 -> 0 | F8: ='10'!E180 -> 0 | G8: ='10'!E224 -> 0 | H8: ='10'!E268 -> 0 | I8: ='10'!E312 -> 0 | J8: ='11'!E48 -> 1 | K8: ='11'!E92 -> 2 | L8: ='11'!E136 -> 3 | M8: ='11'!E180 -> 3 | N8: ='11'!E224 -> 4 | O8: ='11'!E268 -> 1 | P8: ='11'!E312 -> 0 | Q8: ='12'!E48 -> 0 | R8: ='12'!E92 -> 1 | S8: ='12'!E136 -> 0 | T8: ='12'!E180 -> 6 | U8: ='12'!E224 -> 3 | V8: ='12'!E268 -> 1 | W8: ='12'!E312 -> 3 | Y8: 4 | Z8: Sos | AA8: Bio | AB8: B. Jerm | AC8: B. Ing-L | AD8: Ing-L | AE8: B. Jpn | AF8: B. Jpn | AG8: Mat-L | AH8: B. Jerm | AI8: Eko | AJ8: B. Jerm | AK8: Antro | AL8: B. Jpn | AM8: Antro
B9: Kat | C9: ='10'!E49 -> 0 | D9: ='10'!E93 -> 15 | E9: ='10'!E137 -> 0 | F9: ='10'!E181 -> 0 | G9: ='10'!E225 -> 0 | H9: ='10'!E269 -> 0 | I9: ='10'!E313 -> 0 | J9: ='11'!E49 -> 1 | K9: ='11'!E93 -> 0 | L9: ='11'!E137 -> 3 | M9: ='11'!E181 -> 1 | N9: ='11'!E225 -> 3 | O9: ='11'!E269 -> 2 | P9: ='11'!E313 -> 2 | Q9: ='12'!E49 -> 3 | R9: ='12'!E93 -> 1 | S9: ='12'!E137 -> 0 | T9: ='12'!E181 -> 7 | U9: ='12'!E225 -> 0 | V9: ='12'!E269 -> 0 | W9: ='12'!E313 -> 2 | Y9: 5
B10: Musik | C10: ='10'!E50 -> 19 | D10: ='10'!E94 -> 19 | E10: ='10'!E138 -> 0 | F10: ='10'!E182 -> 0 | G10: ='10'!E226 -> 36 | H10: ='10'!E270 -> 36 | I10: ='10'!E314 -> 36 | J10: ='11'!E50 -> 25 | K10: ='11'!E94 -> 26 | L10: ='11'!E138 -> 16 | M10: ='11'!E182 -> 23 | N10: ='11'!E226 -> 28 | O10: ='11'!E270 -> 20 | P10: ='11'!E314 -> 26 | Q10: ='12'!E50 -> 27 | R10: ='12'!E94 -> 20 | S10: ='12'!E138 -> 26 | T10: ='12'!E182 -> 31 | U10: ='12'!E226 -> 15 | V10: ='12'!E270 -> 24 | W10: ='12'!E314 -> 21
B11: Rupa | C11: ='10'!E51 -> 17 | D11: ='10'!E95 -> 17 | E11: ='10'!E139 -> 36 | F11: ='10'!E183 -> 35 | G11: ='10'!E227 -> 0 | H11: ='10'!E271 -> 0 | I11: ='10'!E315 -> 0 | J11: ='11'!E51 -> 11 | K11: ='11'!E95 -> 10 | L11: ='11'!E139 -> 20 | M11: ='11'!E183 -> 13 | N11: ='11'!E227 -> 8 | O11: ='11'!E271 -> 15 | P11: ='11'!E315 -> 10 | Q11: ='12'!E51 -> 9 | R11: ='12'!E95 -> 16 | S11: ='12'!E139 -> 10 | T11: ='12'!E183 -> 5 | U11: ='12'!E227 -> 21 | V11: ='12'!E271 -> 12 | W11: ='12'!E315 -> 11 | Y11: Isl | Z11: 1 | AA11: 1 | AB11: 1 | AC11: 1 | AD11: 1 | AE11: 1 | AF11: 1 | AG11: 1 | AH11: 1 | AI11: 1 | AJ11: 1 | AK11: 1 | AL11: 1 | AM11: 1
Y12: Kri | Z12: 1 | AA12: 1 | AB12: 1 | AC12: 1 | AD12: 1 | AE12: 1 | AH12: 1 | AJ12: 1 | AK12: 1 | AL12: 1 | AM12: 1
B13: Kokurikuler | C13: 1 | D13: 1 | E13: 1 | F13: 1 | G13: 1 | H13: 1 | I13: 1 | Y13: Kat | Z13: 1 | AB13: 1 | AC13: 1 | AD13: 1 | AE13: 1 | AF13: 1 | AG13: 1 | AH13: 1 | AJ13: 1 | AM13: 1
C14: Ihwan | D14: Win | E14: Yay | F14: Yay | G14: Im | H14: Im | I14: Ulin | J14: Debby | K14: April | L14: Sinta | M14: Pur | N14: Sinta | O14: Ihwan | P14: Angg | Q14: Dhi | R14: Dyah | S14: Pur | T14: Debby | U14: Debby | V14: Angg | W14: Angg
B16: Wali | C16: DP | D16: Win | E16: Yay | F16: Amir | G16: Deni | H16: Im | I16: Ulin | J16: Debby | K16: April | L16: Sinta | M16: Pur | N16: Can | O16: Nurul | P16: Angg | Q16: Dewi | R16: Dhi | S16: Agus | T16: Ratna | U16: Is | V16: Ari | W16: Dyah
C18: DP | D18: Win | E18: Yay | F18: Amir | G18: Deni | H18: Im | I18: Ulin | J18: Debby | K18: April | L18: Sinta | M18: Joko | N18: Nurul | O18: Ihwan | P18: Pur | Q18: Dewi | R18: Dyah | S18: Agus | T18: Ratna | U18: Is | V18: Can | W18: Angg
B19: Penjadwalan
B20: Hari | C20: Jam | D20: A | E20: B | F20: C | G20: D | H20: E | I20: Jml
B21: Senin | C21: 10 | I21: =SUM(D21:H21) -> 0
B22: Selasa | C22: 10 | I22: =SUM(D22:H22) -> 0
B23: Rabu | C23: 10 | I23: =SUM(D23:H23) -> 0
B24: Kamis | C24: 10 | I24: =SUM(D24:H24) -> 0 | AG24: SMAN 2 Wonosari
B25: Jumat | C25: 8 | I25: =SUM(D25:H25) -> 0 | AG25: Daftar Mapel Pilihan TA 2025/2026 (lama)
AG26: XII-A | AH26: XII-B | AI26: XII-C | AJ26: XII-D | AK26: XII-E | AL26: XII-F | AM26: XII-G
AG27: Bio | AH27: Bio | AI27: Eko | AJ27: B. Ing-L | AK27: B. Ing-L | AL27: B. Ing-L | AM27: Mat-L
AG28: Kim | AH28: Kim | AI28: Kim | AJ28: Antro | AK28: Sos | AL28: Sos | AM28: Antro
AG29: Sos | AH29: Sos | AI29: Inf | AJ29: Fis | AK29: Geo | AL29: Geo | AM29: Eko
AG30: B. Jerm | AH30: B. Jerm | AI30: B. Jpn | AJ30: Bio | AK30: Fis | AL30: Fis | AM30: B. Jpn
AG31: PKWU | AH31: PKWU | AI31: PKWU | AJ31: PKWU | AK31: PKWU | AL31: PKWU | AM31: PKWU
AG33: Daftar Mapel Pilihan TA 2026/2027 (baru)
AG34: XII-A | AH34: XII-B | AI34: XII-C | AJ34: XII-D | AK34: XII-E | AL34: XII-F | AM34: XII-G
AG35: Bio | AH35: Bio | AI35: Bio | AJ35: Geo | AK35: Geo | AL35: Geo | AM35: Eko
AG36: Fis | AH36: Fis | AI36: Fis | AJ36: Sos | AK36: Sos | AL36: Sos | AM36: B. Ing-L
AG37: Kim | AH37: Kim | AI37: Kim | AJ37: Eko | AK37: Eko | AL37: Eko | AM37: B. Jpn
AG38: Mat-L | AH38: B. Jerm | AI38: Eko | AJ38: B. Jerm | AK38: Antro | AL38: B. Jpn | AM38: Antro
